<?xml version="1.0" ?>
<!-- =================================================================================== -->
<!-- |    This document was autogenerated by xacro from iris.xacro                     | -->
<!-- |    EDITING THIS FILE BY HAND IS NOT RECOMMENDED                                 | -->
<!-- =================================================================================== -->
<!-- To check the URDF and SDF you can run the following
px4_gazebo_wind3d/xacro$ xacro iris.xacro > iris.urdf 
px4_gazebo_wind3d/xacro$ gz sdf -p iris.urdf > iris.sdf
-->
<robot name="iris">
  <!-- =============================================================== -->
  <!-- ==================== ROS INTERFACE MACRO ====================== -->
  <!-- =============================================================== -->
  <!-- <xacro:macro 
  		name="ros_interface_plugin_macro"
  		params="namespace">
    <gazebo>
      <plugin name="ros_interface_plugin" filename="librotors_gazebo_ros_interface_plugin.so">
        <robotNamespace>${namespace}</robotNamespace>
      </plugin>
    </gazebo>
  </xacro:macro>-->
  <link name="/base_link">
    </link>
  <joint name="/base_joint" type="fixed">
    <origin rpy="0 0 0" xyz="0 0 0"/>
    <parent link="/base_link"/>
    <child link="/base_link_inertia"/>
  </joint>
  <link name="/base_link_inertia">
    <inertial>
      <mass value="1.5"/>
      <!-- [kg] -->
      <origin xyz="0 0 0"/>
      <inertia ixx="0.029125" ixy="0.0" ixz="0.0" iyy="0.029125" iyz="0.0" izz="0.055225"/>
    </inertial>
    <visual>
      <origin rpy="0 0 0" xyz="0 0 0"/>
      <geometry>
        <mesh filename="/home2/arwillis/uncc_wind_control/ros_image/ros_ws/src/gazebo_px4_drone/xacro/meshes/iris.dae" scale="1 1 1"/>
      </geometry>
    </visual>
    <collision>
      <origin rpy="0 0 0" xyz="0 0 0"/>
      <geometry>
        <box size="0.47 0.47 0.11"/>
        <!-- [m] [m] [m] -->
      </geometry>
    </collision>
  </link>
  <!-- attach multirotor_base_plugin to the base_link -->
  <gazebo>
    <plugin filename="libgazebo_multirotor_base_plugin.so" name="multirotor_base_plugin">
      <robotNamespace></robotNamespace>
      <linkName>/base_link</linkName>
      <rotorVelocitySlowdownSim>10</rotorVelocitySlowdownSim>
    </plugin>
  </gazebo>
  <gazebo reference="/base_link">
    <material>Gazebo/DarkGrey</material>
  </gazebo>
  <joint name="/rotor_0_joint" type="continuous">
    <origin rpy="0 0 0" xyz="0.13 -0.22 0.023"/>
    <axis xyz="0 0 1"/>
    <!-- TODO(ff): not currently set because it's not yet supported -->
    <!-- <limit effort="2000" velocity="${max_rot_velocity}" /> -->
    <parent link="/base_link"/>
    <child link="/rotor_0"/>
  </joint>
  <link name="/rotor_0">
    <inertial>
      <mass value="0.005"/>
      <!-- [kg] -->
      <inertia ixx="9.7499961e-07" ixy="0.0" ixz="0.0" iyy="0.0002731037965917711" iyz="0.0" izz="0.00027899753423427505"/>
    </inertial>
    <visual>
      <geometry>
        <mesh filename="/home2/arwillis/uncc_wind_control/ros_image/ros_ws/src/gazebo_px4_drone/xacro/meshes/propeller_ccw.dae" scale="0.1 0.1 0.1"/>
        <!-- The propeller meshes have a radius of 1m -->
        <!-- <box size="${2*radius_rotor} 0.01 0.005"/> -->
      </geometry>
    </visual>
    <collision>
      <geometry>
        <cylinder length="0.005" radius="0.1"/>
        <!-- [m] -->
      </geometry>
    </collision>
  </link>
  <gazebo>
    <!-- <plugin name="${robot_namespace}_${suffix}_motor_model" filename="libgazebo_motor_model.so"> -->
    <plugin filename="libgazebo_wind3d_motor_model_plugin.so" name="_motor_model">
      <robotNamespace></robotNamespace>
      <jointName>/rotor_0_joint</jointName>
      <linkName>/rotor_0</linkName>
      <turningDirection>ccw</turningDirection>
      <timeConstantUp>0.0125</timeConstantUp>
      <timeConstantDown>0.025</timeConstantDown>
      <maxRotVelocity>1100</maxRotVelocity>
      <motorConstant>5.84e-06</motorConstant>
      <momentConstant>0.06</momentConstant>
      <commandSubTopic>/gazebo/command/motor_speed</commandSubTopic>
      <motorNumber>0</motorNumber>
      <rotorDragCoefficient>0.000175</rotorDragCoefficient>
      <rollingMomentCoefficient>1e-06</rollingMomentCoefficient>
      <motorSpeedPubTopic>motor_speed/0</motorSpeedPubTopic>
      <rotorVelocitySlowdownSim>10</rotorVelocitySlowdownSim>
    </plugin>
  </gazebo>
  <gazebo reference="/rotor_0">
    <material>Gazebo/Blue</material>
  </gazebo>
  <joint name="/rotor_1_joint" type="continuous">
    <origin rpy="0 0 0" xyz="-0.13 0.2 0.023"/>
    <axis xyz="0 0 1"/>
    <!-- TODO(ff): not currently set because it's not yet supported -->
    <!-- <limit effort="2000" velocity="${max_rot_velocity}" /> -->
    <parent link="/base_link"/>
    <child link="/rotor_1"/>
  </joint>
  <link name="/rotor_1">
    <inertial>
      <mass value="0.005"/>
      <!-- [kg] -->
      <inertia ixx="9.7499961e-07" ixy="0.0" ixz="0.0" iyy="0.0002731037965917711" iyz="0.0" izz="0.00027899753423427505"/>
    </inertial>
    <visual>
      <geometry>
        <mesh filename="/home2/arwillis/uncc_wind_control/ros_image/ros_ws/src/gazebo_px4_drone/xacro/meshes/propeller_ccw.dae" scale="0.1 0.1 0.1"/>
        <!-- The propeller meshes have a radius of 1m -->
        <!-- <box size="${2*radius_rotor} 0.01 0.005"/> -->
      </geometry>
    </visual>
    <collision>
      <geometry>
        <cylinder length="0.005" radius="0.1"/>
        <!-- [m] -->
      </geometry>
    </collision>
  </link>
  <gazebo>
    <!-- <plugin name="${robot_namespace}_${suffix}_motor_model" filename="libgazebo_motor_model.so"> -->
    <plugin filename="libgazebo_wind3d_motor_model_plugin.so" name="_motor_model">
      <robotNamespace></robotNamespace>
      <jointName>/rotor_1_joint</jointName>
      <linkName>/rotor_1</linkName>
      <turningDirection>ccw</turningDirection>
      <timeConstantUp>0.0125</timeConstantUp>
      <timeConstantDown>0.025</timeConstantDown>
      <maxRotVelocity>1100</maxRotVelocity>
      <motorConstant>5.84e-06</motorConstant>
      <momentConstant>0.06</momentConstant>
      <commandSubTopic>/gazebo/command/motor_speed</commandSubTopic>
      <motorNumber>1</motorNumber>
      <rotorDragCoefficient>0.000175</rotorDragCoefficient>
      <rollingMomentCoefficient>1e-06</rollingMomentCoefficient>
      <motorSpeedPubTopic>motor_speed/1</motorSpeedPubTopic>
      <rotorVelocitySlowdownSim>10</rotorVelocitySlowdownSim>
    </plugin>
  </gazebo>
  <gazebo reference="/rotor_1">
    <material>Gazebo/Red</material>
  </gazebo>
  <joint name="/rotor_2_joint" type="continuous">
    <origin rpy="0 0 0" xyz="0.13 0.22 0.023"/>
    <axis xyz="0 0 1"/>
    <!-- TODO(ff): not currently set because it's not yet supported -->
    <!-- <limit effort="2000" velocity="${max_rot_velocity}" /> -->
    <parent link="/base_link"/>
    <child link="/rotor_2"/>
  </joint>
  <link name="/rotor_2">
    <inertial>
      <mass value="0.005"/>
      <!-- [kg] -->
      <inertia ixx="9.7499961e-07" ixy="0.0" ixz="0.0" iyy="0.0002731037965917711" iyz="0.0" izz="0.00027899753423427505"/>
    </inertial>
    <visual>
      <geometry>
        <mesh filename="/home2/arwillis/uncc_wind_control/ros_image/ros_ws/src/gazebo_px4_drone/xacro/meshes/propeller_cw.dae" scale="0.1 0.1 0.1"/>
        <!-- The propeller meshes have a radius of 1m -->
        <!-- <box size="${2*radius_rotor} 0.01 0.005"/> -->
      </geometry>
    </visual>
    <collision>
      <geometry>
        <cylinder length="0.005" radius="0.1"/>
        <!-- [m] -->
      </geometry>
    </collision>
  </link>
  <gazebo>
    <!-- <plugin name="${robot_namespace}_${suffix}_motor_model" filename="libgazebo_motor_model.so"> -->
    <plugin filename="libgazebo_wind3d_motor_model_plugin.so" name="_motor_model">
      <robotNamespace></robotNamespace>
      <jointName>/rotor_2_joint</jointName>
      <linkName>/rotor_2</linkName>
      <turningDirection>cw</turningDirection>
      <timeConstantUp>0.0125</timeConstantUp>
      <timeConstantDown>0.025</timeConstantDown>
      <maxRotVelocity>1100</maxRotVelocity>
      <motorConstant>5.84e-06</motorConstant>
      <momentConstant>0.06</momentConstant>
      <commandSubTopic>/gazebo/command/motor_speed</commandSubTopic>
      <motorNumber>2</motorNumber>
      <rotorDragCoefficient>0.000175</rotorDragCoefficient>
      <rollingMomentCoefficient>1e-06</rollingMomentCoefficient>
      <motorSpeedPubTopic>motor_speed/2</motorSpeedPubTopic>
      <rotorVelocitySlowdownSim>10</rotorVelocitySlowdownSim>
    </plugin>
  </gazebo>
  <gazebo reference="/rotor_2">
    <material>Gazebo/Blue</material>
  </gazebo>
  <joint name="/rotor_3_joint" type="continuous">
    <origin rpy="0 0 0" xyz="-0.13 -0.2 0.023"/>
    <axis xyz="0 0 1"/>
    <!-- TODO(ff): not currently set because it's not yet supported -->
    <!-- <limit effort="2000" velocity="${max_rot_velocity}" /> -->
    <parent link="/base_link"/>
    <child link="/rotor_3"/>
  </joint>
  <link name="/rotor_3">
    <inertial>
      <mass value="0.005"/>
      <!-- [kg] -->
      <inertia ixx="9.7499961e-07" ixy="0.0" ixz="0.0" iyy="0.0002731037965917711" iyz="0.0" izz="0.00027899753423427505"/>
    </inertial>
    <visual>
      <geometry>
        <mesh filename="/home2/arwillis/uncc_wind_control/ros_image/ros_ws/src/gazebo_px4_drone/xacro/meshes/propeller_cw.dae" scale="0.1 0.1 0.1"/>
        <!-- The propeller meshes have a radius of 1m -->
        <!-- <box size="${2*radius_rotor} 0.01 0.005"/> -->
      </geometry>
    </visual>
    <collision>
      <geometry>
        <cylinder length="0.005" radius="0.1"/>
        <!-- [m] -->
      </geometry>
    </collision>
  </link>
  <gazebo>
    <!-- <plugin name="${robot_namespace}_${suffix}_motor_model" filename="libgazebo_motor_model.so"> -->
    <plugin filename="libgazebo_wind3d_motor_model_plugin.so" name="_motor_model">
      <robotNamespace></robotNamespace>
      <jointName>/rotor_3_joint</jointName>
      <linkName>/rotor_3</linkName>
      <turningDirection>cw</turningDirection>
      <timeConstantUp>0.0125</timeConstantUp>
      <timeConstantDown>0.025</timeConstantDown>
      <maxRotVelocity>1100</maxRotVelocity>
      <motorConstant>5.84e-06</motorConstant>
      <momentConstant>0.06</momentConstant>
      <commandSubTopic>/gazebo/command/motor_speed</commandSubTopic>
      <motorNumber>3</motorNumber>
      <rotorDragCoefficient>0.000175</rotorDragCoefficient>
      <rollingMomentCoefficient>1e-06</rollingMomentCoefficient>
      <motorSpeedPubTopic>motor_speed/3</motorSpeedPubTopic>
      <rotorVelocitySlowdownSim>10</rotorVelocitySlowdownSim>
    </plugin>
  </gazebo>
  <gazebo reference="/rotor_3">
    <material>Gazebo/Red</material>
  </gazebo>
  <gazebo>
    <link name="/vis_body">
      <inertial>
        <mass>1e-9</mass>
        <inertia>
          <ixx>1e-9</ixx>
          <ixy>0</ixy>
          <ixz>0</ixz>
          <iyy>1e-9</iyy>
          <iyz>0</iyz>
          <izz>1e-9</izz>
        </inertia>
        <pose>0 0 0.0 0 -0 0</pose>
      </inertial>
      <collision name="collision">
        <geometry>
          <sphere>
            <radius>0.001</radius>
          </sphere>
        </geometry>
      </collision>
      <visual name="visual">
        <plugin filename="libgazebo_wind3d_visual_plugin.so" name="sphere_wind3d_visual"/>
        <geometry>
          <sphere>
            <radius>0.001</radius>
          </sphere>
        </geometry>
      </visual>
    </link>
    <joint name="/vis/base_joint" type="revolute">
      <child>/vis_body</child>
      <parent>/base_link</parent>
      <axis>
        <xyz>1 0 0</xyz>
        <limit>
          <lower>0</lower>
          <upper>0</upper>
          <effort>0</effort>
          <velocity>0</velocity>
        </limit>
        <dynamics>
          <spring_reference>0</spring_reference>
          <spring_stiffness>0</spring_stiffness>
        </dynamics>
        <use_parent_model_frame>1</use_parent_model_frame>
      </axis>
    </joint>
  </gazebo>
  <gazebo>
    <link name="/imu_link">
      <pose>0 0 0.02 0 0 0</pose>
      <inertial>
        <pose>0 0 0 0 0 0</pose>
        <mass>0.015</mass>
        <inertia>
          <ixx>1e-05</ixx>
          <ixy>0</ixy>
          <ixz>0</ixz>
          <iyy>1e-05</iyy>
          <iyz>0</iyz>
          <izz>1e-05</izz>
        </inertia>
      </inertial>
    </link>
    <joint name="/imu_joint" type="revolute">
      <child>/imu_link</child>
      <parent>/base_link</parent>
      <axis>
        <xyz>1 0 0</xyz>
        <limit>
          <lower>0</lower>
          <upper>0</upper>
          <effort>0</effort>
          <velocity>0</velocity>
        </limit>
        <dynamics>
          <spring_reference>0</spring_reference>
          <spring_stiffness>0</spring_stiffness>
        </dynamics>
        <use_parent_model_frame>1</use_parent_model_frame>
      </axis>
    </joint>
    <include>
      <uri>model://gps</uri>
      <pose>0.05 0 0.04 0 0 0</pose>
      <name>gps0</name>
    </include>
    <joint name="gps0_joint" type="fixed">
      <child>gps0::link</child>
      <parent>/base_link</parent>
    </joint>
    <plugin filename="libgazebo_groundtruth_plugin.so" name="groundtruth_plugin">
      <robotNamespace/>
    </plugin>
    <plugin filename="libgazebo_anemometer_plugin.so" name="anemometer_plugin">
      <robotNamespace/>
      <linkName>/base_link</linkName>
      <pubRate>10</pubRate>
      <noiseX>0.0000</noiseX>
      <noiseY>0.0000</noiseY>
      <noiseZ>0.0000</noiseZ>
      <publishRate>5</publishRate>
      <anemometerTopic>/iris/anemometer</anemometerTopic>
      <windPubTopic>world_wind</windPubTopic>
      <windServerRegisterLinkTopic>/gazebo/default/world_wind_register_link</windServerRegisterLinkTopic>
      <windServerLinkTopic>/gazebo/default/anemometer_wind</windServerLinkTopic>
    </plugin>
    <plugin filename="libgazebo_dynamic_wind_plugin.so" name="gazebo_dynamic_wind_plugin">
      <robotNamespace/>
      <frameId>world</frameId>
      <linkName>/base_link</linkName>
      <publishRate>5</publishRate>
      <windServerRegisterLinkTopic>/gazebo/default/world_wind_register_link</windServerRegisterLinkTopic>
      <windServerLinkTopic>/gazebo/default/dynamics_wind</windServerLinkTopic>
    </plugin>
    <plugin filename="libgazebo_magnetometer_plugin.so" name="magnetometer_plugin">
      <robotNamespace/>
      <pubRate>100</pubRate>
      <noiseDensity>0.0004</noiseDensity>
      <randomWalk>6.4e-06</randomWalk>
      <biasCorrelationTime>600</biasCorrelationTime>
      <magTopic>/mag</magTopic>
    </plugin>
    <plugin filename="libgazebo_barometer_plugin.so" name="barometer_plugin">
      <robotNamespace/>
      <pubRate>50</pubRate>
      <baroTopic>/baro</baroTopic>
      <baroDriftPaPerSec>0</baroDriftPaPerSec>
    </plugin>
    <plugin filename="libgazebo_mavlink_interface.so" name="mavlink_interface">
      <robotNamespace/>
      <imuSubTopic>/imu</imuSubTopic>
      <magSubTopic>/mag</magSubTopic>
      <baroSubTopic>/baro</baroSubTopic>
      <mavlink_addr>INADDR_ANY</mavlink_addr>
      <mavlink_tcp_port>4560</mavlink_tcp_port>
      <mavlink_udp_port>14560</mavlink_udp_port>
      <serialEnabled>0</serialEnabled>
      <serialDevice>/dev/ttyACM0</serialDevice>
      <baudRate>921600</baudRate>
      <qgc_addr>INADDR_ANY</qgc_addr>
      <qgc_udp_port>14550</qgc_udp_port>
      <sdk_addr>INADDR_ANY</sdk_addr>
      <sdk_udp_port>14540</sdk_udp_port>
      <hil_mode>0</hil_mode>
      <hil_state_level>0</hil_state_level>
      <send_vision_estimation>0</send_vision_estimation>
      <send_odometry>1</send_odometry>
      <enable_lockstep>1</enable_lockstep>
      <use_tcp>1</use_tcp>
      <motorSpeedCommandPubTopic>/gazebo/command/motor_speed</motorSpeedCommandPubTopic>
      <control_channels>
        <channel name="rotor1">
          <input_index>0</input_index>
          <input_offset>0</input_offset>
          <input_scaling>1000</input_scaling>
          <zero_position_disarmed>0</zero_position_disarmed>
          <zero_position_armed>100</zero_position_armed>
          <joint_control_type>velocity</joint_control_type>
        </channel>
        <channel name="rotor2">
          <input_index>1</input_index>
          <input_offset>0</input_offset>
          <input_scaling>1000</input_scaling>
          <zero_position_disarmed>0</zero_position_disarmed>
          <zero_position_armed>100</zero_position_armed>
          <joint_control_type>velocity</joint_control_type>
        </channel>
        <channel name="rotor3">
          <input_index>2</input_index>
          <input_offset>0</input_offset>
          <input_scaling>1000</input_scaling>
          <zero_position_disarmed>0</zero_position_disarmed>
          <zero_position_armed>100</zero_position_armed>
          <joint_control_type>velocity</joint_control_type>
        </channel>
        <channel name="rotor4">
          <input_index>3</input_index>
          <input_offset>0</input_offset>
          <input_scaling>1000</input_scaling>
          <zero_position_disarmed>0</zero_position_disarmed>
          <zero_position_armed>100</zero_position_armed>
          <joint_control_type>velocity</joint_control_type>
        </channel>
        <channel name="rotor5">
          <input_index>4</input_index>
          <input_offset>1</input_offset>
          <input_scaling>324.6</input_scaling>
          <zero_position_disarmed>0</zero_position_disarmed>
          <zero_position_armed>0</zero_position_armed>
          <joint_control_type>velocity</joint_control_type>
          <joint_control_pid>
            <p>0.1</p>
            <i>0</i>
            <d>0</d>
            <iMax>0.0</iMax>
            <iMin>0.0</iMin>
            <cmdMax>2</cmdMax>
            <cmdMin>-2</cmdMin>
          </joint_control_pid>
          <joint_name>zephyr_delta_wing::propeller_joint</joint_name>
        </channel>
        <channel name="rotor6">
          <input_index>5</input_index>
          <input_offset>0</input_offset>
          <input_scaling>0.524</input_scaling>
          <zero_position_disarmed>0</zero_position_disarmed>
          <zero_position_armed>0</zero_position_armed>
          <joint_control_type>position</joint_control_type>
          <joint_name>zephyr_delta_wing::flap_left_joint</joint_name>
          <joint_control_pid>
            <p>10.0</p>
            <i>0</i>
            <d>0</d>
            <iMax>0</iMax>
            <iMin>0</iMin>
            <cmdMax>20</cmdMax>
            <cmdMin>-20</cmdMin>
          </joint_control_pid>
        </channel>
        <channel name="rotor7">
          <input_index>6</input_index>
          <input_offset>0</input_offset>
          <input_scaling>0.524</input_scaling>
          <zero_position_disarmed>0</zero_position_disarmed>
          <zero_position_armed>0</zero_position_armed>
          <joint_control_type>position</joint_control_type>
          <joint_name>zephyr_delta_wing::flap_right_joint</joint_name>
          <joint_control_pid>
            <p>10.0</p>
            <i>0</i>
            <d>0</d>
            <iMax>0</iMax>
            <iMin>0</iMin>
            <cmdMax>20</cmdMax>
            <cmdMin>-20</cmdMin>
          </joint_control_pid>
        </channel>
        <channel name="rotor8">
          <input_index>7</input_index>
          <input_offset>0</input_offset>
          <input_scaling>0.524</input_scaling>
          <zero_position_disarmed>0</zero_position_disarmed>
          <zero_position_armed>0</zero_position_armed>
          <joint_control_type>position</joint_control_type>
        </channel>
      </control_channels>
    </plugin>
    <static>0</static>
    <plugin filename="libgazebo_imu_plugin.so" name="rotors_gazebo_imu_plugin">
      <robotNamespace/>
      <linkName>/imu_link</linkName>
      <imuTopic>/imu</imuTopic>
      <gyroscopeNoiseDensity>0.00018665</gyroscopeNoiseDensity>
      <gyroscopeRandomWalk>3.8785e-05</gyroscopeRandomWalk>
      <gyroscopeBiasCorrelationTime>1000.0</gyroscopeBiasCorrelationTime>
      <gyroscopeTurnOnBiasSigma>0.0087</gyroscopeTurnOnBiasSigma>
      <accelerometerNoiseDensity>0.00186</accelerometerNoiseDensity>
      <accelerometerRandomWalk>0.006</accelerometerRandomWalk>
      <accelerometerBiasCorrelationTime>300.0</accelerometerBiasCorrelationTime>
      <accelerometerTurnOnBiasSigma>0.196</accelerometerTurnOnBiasSigma>
    </plugin>
  </gazebo>
  <!--    <gazebo>
            <include>
      <uri>model://stereo_camera</uri>
      <pose>0.1 0 0 0 0 0</pose>
    </include>
    <joint name="stereo_camera_joint" type="revolute">
      <child>stereo_camera::link</child>
      <parent>iris::base_link</parent>
      <axis>
        <xyz>0 0 1</xyz>
        <limit>
          <upper>0</upper>
          <lower>0</lower>
        </limit>
      </axis>
    </joint>
    </gazebo>-->
</robot>

